<?xml version="1.0" encoding="utf-8"?>
<!-- =================================================================================== -->
<!-- |    This document was autogenerated by xacro from ur3_visual_grabbing_with_rg2.xacro | -->
<!-- |    EDITING THIS FILE BY HAND IS NOT RECOMMENDED                                 | -->
<!-- =================================================================================== -->
<robot name="ur3_visual_grabbing">

  <!-- measured from model -->
  <link name="base_link">
    <visual>
      <geometry>
        <mesh filename="package://ur3/meshes/ur3/visual/base.dae"/>
      </geometry>
      <material name="LightGrey">
        <color rgba="0.7 0.7 0.7 1.0"/>
      </material>
    </visual>
    <collision>
      <geometry>
        <mesh filename="package://ur3/meshes/ur3/collision/base.stl"/>
      </geometry>
    </collision>
    <inertial>
      <mass value="2.0"/>
      <origin rpy="0 0 0" xyz="0.0 0.0 0.0"/>
      <inertia ixx="0.0030531654454" ixy="0.0" ixz="0.0" iyy="0.0030531654454" iyz="0.0" izz="0.005625"/>
    </inertial>
  </link>
  <joint name="shoulder_pan_joint" type="revolute">
    <parent link="base_link"/>
    <child link="shoulder_link"/>
    <origin rpy="0.0 0.0 0.0" xyz="0.0 0.0 0.1519"/>
    <axis xyz="0 0 1"/>
    <limit effort="330.0" lower="-3.14159265359" upper="3.14159265359" velocity="2.16"/>
    <dynamics damping="0.0" friction="0.0"/>
  </joint>
  <link name="shoulder_link">
    <visual>
      <geometry>
        <mesh filename="package://ur3/meshes/ur3/visual/shoulder.dae"/>
      </geometry>
      <material name="LightGrey">
        <color rgba="0.7 0.7 0.7 1.0"/>
      </material>
    </visual>
    <collision>
      <geometry>
        <mesh filename="package://ur3/meshes/ur3/collision/shoulder.stl"/>
      </geometry>
    </collision>
    <inertial>
      <mass value="2.0"/>
      <origin rpy="0 0 0" xyz="0.0 0.0 0.0"/>
      <inertia ixx="0.0080931634294" ixy="0.0" ixz="0.0" iyy="0.0080931634294" iyz="0.0" izz="0.005625"/>
    </inertial>
  </link>
  <joint name="shoulder_lift_joint" type="revolute">
    <parent link="shoulder_link"/>
    <child link="upper_arm_link"/>
    <origin rpy="0.0 1.57079632679 0.0" xyz="0.0 0.1198 0.0"/>
    <axis xyz="0 1 0"/>
    <limit effort="330.0" lower="-3.14159265359" upper="3.14159265359" velocity="2.16"/>
    <dynamics damping="0.0" friction="0.0"/>
  </joint>
  <link name="upper_arm_link">
    <visual>
      <geometry>
        <mesh filename="package://ur3/meshes/ur3/visual/upperarm.dae"/>
      </geometry>
      <material name="LightGrey">
        <color rgba="0.7 0.7 0.7 1.0"/>
      </material>
    </visual>
    <collision>
      <geometry>
        <mesh filename="package://ur3/meshes/ur3/collision/upperarm.stl"/>
      </geometry>
    </collision>
    <inertial>
      <mass value="3.42"/>
      <origin rpy="0 0 0" xyz="0.0 0.0 0.121825"/>
      <inertia ixx="0.0217284832211" ixy="0.0" ixz="0.0" iyy="0.0217284832211" iyz="0.0" izz="0.00961875"/>
    </inertial>
  </link>
  <joint name="elbow_joint" type="revolute">
    <parent link="upper_arm_link"/>
    <child link="forearm_link"/>
    <origin rpy="0.0 0.0 0.0" xyz="0.0 -0.0925 0.24365"/>
    <axis xyz="0 1 0"/>
    <limit effort="150.0" lower="-3.14159265359" upper="3.14159265359" velocity="3.15"/>
    <dynamics damping="0.0" friction="0.0"/>
  </joint>
  <link name="forearm_link">
    <visual>
      <geometry>
        <mesh filename="package://ur3/meshes/ur3/visual/forearm.dae"/>
      </geometry>
      <material name="LightGrey">
        <color rgba="0.7 0.7 0.7 1.0"/>
      </material>
    </visual>
    <collision>
      <geometry>
        <mesh filename="package://ur3/meshes/ur3/collision/forearm.stl"/>
      </geometry>
    </collision>
    <inertial>
      <mass value="1.26"/>
      <origin rpy="0 0 0" xyz="0.0 0.0 0.106625"/>
      <inertia ixx="0.00654680644378" ixy="0.0" ixz="0.0" iyy="0.00654680644378" iyz="0.0" izz="0.00354375"/>
    </inertial>
  </link>
  <joint name="wrist_1_joint" type="revolute">
    <parent link="forearm_link"/>
    <child link="wrist_1_link"/>
    <origin rpy="0.0 1.57079632679 0.0" xyz="0.0 0.0 0.21325"/>
    <axis xyz="0 1 0"/>
    <limit effort="54.0" lower="-3.14159265359" upper="3.14159265359" velocity="3.2"/>
    <dynamics damping="0.0" friction="0.0"/>
  </joint>
  <link name="wrist_1_link">
    <visual>
      <geometry>
        <mesh filename="package://ur3/meshes/ur3/visual/wrist1.dae"/>
      </geometry>
      <material name="LightGrey">
        <color rgba="0.7 0.7 0.7 1.0"/>
      </material>
    </visual>
    <collision>
      <geometry>
        <mesh filename="package://ur3/meshes/ur3/collision/wrist1.stl"/>
      </geometry>
    </collision>
    <inertial>
      <mass value="0.8"/>
      <origin rpy="0 0 0" xyz="0.0 0.08505 0.0"/>
      <inertia ixx="0.002084999166" ixy="0.0" ixz="0.0" iyy="0.002084999166" iyz="0.0" izz="0.00225"/>
    </inertial>
  </link>
  <joint name="wrist_2_joint" type="revolute">
    <parent link="wrist_1_link"/>
    <child link="wrist_2_link"/>
    <origin rpy="0.0 0.0 0.0" xyz="0.0 0.08505 0.0"/>
    <axis xyz="0 0 1"/>
    <limit effort="54.0" lower="-3.14159265359" upper="3.14159265359" velocity="3.2"/>
    <dynamics damping="0.0" friction="0.0"/>
  </joint>
  <link name="wrist_2_link">
    <visual>
      <geometry>
        <mesh filename="package://ur3/meshes/ur3/visual/wrist2.dae"/>
      </geometry>
      <material name="LightGrey">
        <color rgba="0.7 0.7 0.7 1.0"/>
      </material>
    </visual>
    <collision>
      <geometry>
        <mesh filename="package://ur3/meshes/ur3/collision/wrist2.stl"/>
      </geometry>
    </collision>
    <inertial>
      <mass value="0.8"/>
      <origin rpy="0 0 0" xyz="0.0 0.0 0.08535"/>
      <inertia ixx="0.002084999166" ixy="0.0" ixz="0.0" iyy="0.002084999166" iyz="0.0" izz="0.00225"/>
    </inertial>
  </link>
  <joint name="wrist_3_joint" type="revolute">
    <parent link="wrist_2_link"/>
    <child link="wrist_3_link"/>
    <origin rpy="0.0 0.0 0.0" xyz="0.0 0.0 0.08535"/>
    <axis xyz="0 1 0"/>
    <limit effort="54.0" lower="-3.14159265359" upper="3.14159265359" velocity="3.2"/>
    <dynamics damping="0.0" friction="0.0"/>
  </joint>
  <link name="wrist_3_link">
    <visual>
      <geometry>
        <mesh filename="package://ur3/meshes/ur3/visual/wrist3.dae"/>
      </geometry>
      <material name="LightGrey">
        <color rgba="0.7 0.7 0.7 1.0"/>
      </material>
    </visual>
    <collision>
      <geometry>
        <mesh filename="package://ur3/meshes/ur3/collision/wrist3.stl"/>
      </geometry>
    </collision>
    <inertial>
      <mass value="0.35"/>
      <origin rpy="1.57079632679 0 0" xyz="0.0 0.0619 0.0"/>
      <inertia ixx="0.00013626661216" ixy="0.0" ixz="0.0" iyy="0.00013626661216" iyz="0.0" izz="0.0001792"/>
    </inertial>
  </link>
  <joint name="ee_fixed_joint" type="fixed">
    <parent link="wrist_3_link"/>
    <child link="ee_link"/>
    <origin rpy="0.0 0.0 1.57079632679" xyz="0.0 0.0819 0.0"/>
  </joint>
  <link name="ee_link">
    <collision>
      <geometry>
        <box size="0.01 0.01 0.01"/>
      </geometry>
      <origin rpy="0 0 0" xyz="-0.01 0 0"/>
    </collision>
  </link>
  <transmission name="shoulder_pan_trans">
    <type>transmission_interface/SimpleTransmission</type>
    <joint name="shoulder_pan_joint">
      <hardwareInterface>hardware_interface/PositionJointInterface</hardwareInterface>
    </joint>
    <actuator name="shoulder_pan_motor">
      <mechanicalReduction>1</mechanicalReduction>
    </actuator>
  </transmission>
  <transmission name="shoulder_lift_trans">
    <type>transmission_interface/SimpleTransmission</type>
    <joint name="shoulder_lift_joint">
      <hardwareInterface>hardware_interface/PositionJointInterface</hardwareInterface>
    </joint>
    <actuator name="shoulder_lift_motor">
      <mechanicalReduction>1</mechanicalReduction>
    </actuator>
  </transmission>
  <transmission name="elbow_trans">
    <type>transmission_interface/SimpleTransmission</type>
    <joint name="elbow_joint">
      <hardwareInterface>hardware_interface/PositionJointInterface</hardwareInterface>
    </joint>
    <actuator name="elbow_motor">
      <mechanicalReduction>1</mechanicalReduction>
    </actuator>
  </transmission>
  <transmission name="wrist_1_trans">
    <type>transmission_interface/SimpleTransmission</type>
    <joint name="wrist_1_joint">
      <hardwareInterface>hardware_interface/PositionJointInterface</hardwareInterface>
    </joint>
    <actuator name="wrist_1_motor">
      <mechanicalReduction>1</mechanicalReduction>
    </actuator>
  </transmission>
  <transmission name="wrist_2_trans">
    <type>transmission_interface/SimpleTransmission</type>
    <joint name="wrist_2_joint">
      <hardwareInterface>hardware_interface/PositionJointInterface</hardwareInterface>
    </joint>
    <actuator name="wrist_2_motor">
      <mechanicalReduction>1</mechanicalReduction>
    </actuator>
  </transmission>
  <transmission name="wrist_3_trans">
    <type>transmission_interface/SimpleTransmission</type>
    <joint name="wrist_3_joint">
      <hardwareInterface>hardware_interface/PositionJointInterface</hardwareInterface>
    </joint>
    <actuator name="wrist_3_motor">
      <mechanicalReduction>1</mechanicalReduction>
    </actuator>
  </transmission>

  <!-- ROS base_link to UR 'Base' Coordinates transform -->
  <link name="base"/>
  <joint name="base_link-base_fixed_joint" type="fixed">
    <!-- NOTE: this rotation is only needed as long as base_link itself is
                 not corrected wrt the real robot (ie: rotated over 180
                 degrees)
      -->
    <origin rpy="0 0 -3.14159265359" xyz="0 0 0"/>
    <parent link="base_link"/>
    <child link="base"/>
  </joint>
  <!-- Frame coincident with all-zeros TCP on UR controller -->
  <link name="tool0"/>
  <joint name="wrist_3_link-tool0_fixed_joint" type="fixed">
    <origin rpy="-1.57079632679 0 0" xyz="0 0.0819 0"/>
    <parent link="wrist_3_link"/>
    <child link="tool0"/>
  </joint>
  <link name="world"/>
  <joint name="world_joint" type="fixed">
    <parent link="world"/>
    <child link="base_link"/>
    <origin rpy="0.0 0.0 0.0" xyz="0.0 0.0 0.0"/>
  </joint>
  <!-- mount the fts to the robot -->
  <joint name="ft300_fix" type="fixed">
    <origin rpy="0 0 0" xyz="0 0 0"/>
    <parent link="tool0"/>
    <child link="ft300_mounting_plate"/>
  </joint>
  <!-- Link representing the FT300 force-torque sensor -->
  <link name="ft300_sensor">
    <inertial>
      <origin rpy="0 0 0" xyz="0 0 -0.017"/>
      <mass value="0.300"/>
      <inertia ixx="0.000262" ixy="0" ixz="1e-06" iyx="0" iyy="0.000265" iyz="1e-06" izx="-1e-06" izy="1e-06" izz="0.000219"/>
    </inertial>
    <visual>
      <origin rpy="0 0 0" xyz="0 0 0"/>
      <geometry>
        <mesh filename="package://ur3/meshes/robotiq_ft_sensor/visual/robotiq_ft300.STL"/>
      </geometry>
      <material name="Robotiq-Black">
        <color rgba="0.2 0.2 0.2 1.0"/>
      </material>
    </visual>
    <collision>
      <origin rpy="0 0 0" xyz="0 0 0"/>
      <geometry>
        <mesh filename="package://ur3/meshes/robotiq_ft_sensor/collision/robotiq_ft300.STL"/>
      </geometry>
    </collision>
  </link>
  <!-- Link representing the FT300 mounting plate -->
  <link name="ft300_mounting_plate">
    <visual>
      <origin rpy="0 0 0" xyz="0 0 0"/>
      <geometry>
        <mesh filename="package://ur3/meshes/robotiq_ft_sensor/visual/mountings/robotiq_ft300-G-062-COUPLING_G-50-4M6-1D6_20181119.STL"/>
      </geometry>
      <material name="Robotiq-Grey">
        <color rgba="0.4 0.4 0.4 1.0"/>
      </material>
    </visual>
    <collision>
      <origin rpy="0 0 0" xyz="0 0 0"/>
      <geometry>
        <mesh filename="package://ur3/meshes/robotiq_ft_sensor/collision/mountings/robotiq_ft300-G-062-COUPLING_G-50-4M6-1D6_20181119.STL"/>
      </geometry>
    </collision>
  </link>
  <!-- Connect force sensor with mounting/coupling plate -->
  <joint name="ft300_mounting_plate" type="fixed">
    <origin rpy="0 3.14159265359 0" xyz="0 0 0.0415"/>
    <parent link="ft300_mounting_plate"/>
    <child link="ft300_sensor"/>
  </joint>
  <!-- FORCE REFERENCE FRAME _______________________________________________________________________________
            As specified in the documentation:
            - The Z axis passes through the center of the depression with positive direction in the tool direction.
            - The X axis traces a symmetric line centered on the connector; the positive direction
                points the opposite way away from the connector.
            - The Y axis uses the right hand thumb rule according to X-Z. -->
  <joint name="measurment_joint" type="fixed">
    <origin rpy="0 3.14159265359 -1.57079632679" xyz="0 0 0"/>
    <parent link="ft300_sensor"/>
    <child link="robotiq_ft_frame_id"/>
  </joint>
  <link name="robotiq_ft_frame_id"/>
  <joint name="gripper_base_joint" type="fixed">
    <parent link="robotiq_ft_frame_id"/>
    <child link="gripper_base_link"/>
    <origin rpy="0 0 -1.57079632679" xyz="0 0 0"/>
  </joint>
  <link name="gripper_base_link">
    <inertial>
      <origin rpy="0 0 0" xyz="-0.000118835633453291 4.70054905894546E-06 0.0572680906518555"/>
      <mass value="0.199035856566616"/>
      <inertia ixx="0.000170600248402307" ixy="3.75673847481297E-08" ixz="4.71579777629836E-08" iyy="0.000213152093040191" iyz="-1.76513863534777E-07" izz="5.59878626220752E-05"/>
    </inertial>
    <visual>
      <origin rpy="0 0 0" xyz="0 0 0"/>
      <geometry>
        <mesh filename="package://ur3/meshes/onrobot_rg2/visual/gripper_base_link.dae"/>
      </geometry>
      <material name="White">
        <color rgba="1 1 1 1"/>
      </material>
    </visual>
    <collision>
      <origin rpy="0 0 0" xyz="0 0 0"/>
      <geometry>
        <mesh filename="package://ur3/meshes/onrobot_rg2/collision/gripper_base_link.STL"/>
      </geometry>
    </collision>
  </link>

  <link name="gripper_finger1_finger_link">
    <contact>
      <lateral_friction value="1.0"/>
      <spinning_friction value="1.5"/>
    </contact>
    <inertial>
      <origin rpy="0 0 0" xyz="0.0010718088996676 0.0103000002725817 0.00719447424225184"/>
      <mass value="0.0157597232324457"/>
      <inertia ixx="4.77930907548385E-06" ixy="-3.38189802725612E-15" ixz="-1.64279014982784E-07" iyy="4.865441590744E-06" iyz="-1.3392990014795E-14" izz="1.31307089078094E-06"/>
    </inertial>
    <visual>
      <origin rpy="0 0 0" xyz="0 0 0"/>
      <geometry>
        <mesh filename="package://ur3/meshes/onrobot_rg2/visual/gripper_finger1_finger_link.dae"/>
      </geometry>
      <material name="White">
        <color rgba="1 1 1 1"/>
      </material>
    </visual>
    <collision>
      <origin rpy="0 0 0" xyz="0 0 0"/>
      <geometry>
        <mesh filename="package://ur3/meshes/onrobot_rg2/collision/gripper_finger1_finger_link.STL"/>
      </geometry>
    </collision>
  </link>

  <joint name="gripper_finger1_joint" type="revolute">
    <origin rpy="0 0 0" xyz="0.0169 -0.0103 0.105"/>
    <parent link="gripper_base_link"/>
    <child link="gripper_finger1_finger_link"/>
    <axis xyz="0 1 0"/>
    <limit effort="1000" lower="0" upper="0.8" velocity="2"/>
  </joint>
  <link name="gripper_finger1_inner_knuckle_link">
    <contact>
      <lateral_friction value="1.0"/>
      <spinning_friction value="1.5"/>
    </contact>
    <inertial>
      <origin rpy="0 0 0" xyz="0.000752725541911719 0.00999999924320924 0.0203934641019564"/>
      <mass value="0.00491742236496327"/>
      <inertia ixx="1.98120134788244E-06" ixy="-6.4357476071842E-14" ixz="-6.20941625040096E-08" iyy="1.77599017859716E-06" iyz="-1.09055934131207E-14" izz="2.48948112270257E-07"/>
    </inertial>
    <visual>
      <origin rpy="0 0 0" xyz="0 0 0"/>
      <geometry>
        <mesh filename="package://ur3/meshes/onrobot_rg2/visual/gripper_finger1_inner_knuckle_link.dae"/>
      </geometry>
      <material name="White">
        <color rgba="1 1 1 1"/>
      </material>
    </visual>
    <collision>
      <origin rpy="0 0 0" xyz="0 0 0"/>
      <geometry>
        <mesh filename="package://ur3/meshes/onrobot_rg2/collision/gripper_finger1_inner_knuckle_link.STL"/>
      </geometry>
    </collision>
  </link>

  <joint name="gripper_finger1_inner_knuckle_joint" type="continuous">
    <origin rpy="0 0 0" xyz="0.0074 -0.01 0.1215"/>
    <parent link="gripper_base_link"/>
    <child link="gripper_finger1_inner_knuckle_link"/>
    <axis xyz="0 1 0"/>
    <limit effort="0.1" lower="-3.14" upper="3.14" velocity="100"/>
    <mimic joint="gripper_finger1_joint" offset="0"/>
  </joint>
  <link name="gripper_finger1_finger_tip_link">
    <contact>
      <lateral_friction value="1.0"/>
      <spinning_friction value="1.5"/>
    </contact>
    <inertial>
      <origin rpy="0 0 0" xyz="-0.0011594416667826 0.00580000072518588 0.0107764194581964"/>
      <mass value="0.00872849065417813"/>
      <inertia ixx="1.50886455139492E-06" ixy="-1.78552626714452E-14" ixz="2.60234059895028E-07" iyy="1.45214737233688E-06" iyz="9.35094538565976E-14" izz="3.57695503495602E-07"/>
    </inertial>
    <visual>
      <origin rpy="0 0 0" xyz="0 0 0"/>
      <geometry>
        <mesh filename="package://ur3/meshes/onrobot_rg2/visual/gripper_finger1_finger_tip_link.dae"/>
      </geometry>
      <material name="White">
        <color rgba="1 1 1 1"/>
      </material>
    </visual>
    <collision>
      <origin rpy="0 0 0" xyz="0 0 0"/>
      <geometry>
        <mesh filename="package://ur3/meshes/onrobot_rg2/collision/gripper_finger1_finger_tip_link.STL"/>
      </geometry>
    </collision>
  </link>

  <joint name="gripper_finger1_finger_tip_joint" type="continuous">
    <origin rpy="0 0 0" xyz="0.002 0.0042 0.054964"/>
    <parent link="gripper_finger1_inner_knuckle_link"/>
    <child link="gripper_finger1_finger_tip_link"/>
    <axis xyz="0 1 0"/>
    <limit effort="0.1" lower="-3.14" upper="3.14" velocity="100"/>
    <mimic joint="gripper_finger1_joint" multiplier="-1"/>
  </joint>

  <link name="gripper_finger2_finger_link">
    <contact>
      <lateral_friction value="1.0"/>
      <spinning_friction value="1.5"/>
    </contact>
    <inertial>
      <origin rpy="0 0 0" xyz="-0.00107180889966652 0.0102999997274183 0.00719447424225199"/>
      <mass value="0.0157597232324457"/>
      <inertia ixx="4.7793090754839E-06" ixy="-3.38189802615458E-15" ixz="1.64279014982266E-07" iyy="4.865441590744E-06" iyz="1.33929898462312E-14" izz="1.31307089078089E-06"/>
    </inertial>
    <visual>
      <origin rpy="0 0 0" xyz="0 0 0"/>
      <geometry>
        <mesh filename="package://ur3/meshes/onrobot_rg2/visual/gripper_finger2_finger_link.dae"/>
      </geometry>
      <material name="White">
        <color rgba="1 1 1 1"/>
      </material>
    </visual>
    <collision>
      <origin rpy="0 0 0" xyz="0 0 0"/>
      <geometry>
        <mesh filename="package://ur3/meshes/onrobot_rg2/collision/gripper_finger2_finger_link.STL"/>
      </geometry>
    </collision>
  </link>

  <joint name="gripper_finger2_joint" type="revolute">
    <origin rpy="0 0 0" xyz="-0.0171 -0.0103 0.105"/>
    <parent link="gripper_base_link"/>
    <child link="gripper_finger2_finger_link"/>
    <axis xyz="0 1 0"/>
    <limit effort="1000" lower="-3.14" upper="3.14" velocity="100"/>
    <mimic joint="gripper_finger1_joint" multiplier="-1"/>
  </joint>
  <link name="gripper_finger2_inner_knuckle_link">
    <contact>
      <lateral_friction value="1.0"/>
      <spinning_friction value="1.5"/>
    </contact>
    <inertial>
      <origin rpy="0 0 0" xyz="-0.000752725541908486 0.0100000007567908 0.0203934641019566"/>
      <mass value="0.00491742236496327"/>
      <inertia ixx="1.98120134788246E-06" ixy="-6.43574760392122E-14" ixz="6.20941625037353E-08" iyy="1.77599017859716E-06" iyz="1.09055934323118E-14" izz="2.48948112270238E-07"/>
    </inertial>
    <visual>
      <origin rpy="0 0 0" xyz="0 0 0"/>
      <geometry>
        <mesh filename="package://ur3/meshes/onrobot_rg2/visual/gripper_finger2_inner_knuckle_link.dae"/>
      </geometry>
      <material name="White">
        <color rgba="1 1 1 1"/>
      </material>
    </visual>
    <collision>
      <origin rpy="0 0 0" xyz="0 0 0"/>
      <geometry>
        <mesh filename="package://ur3/meshes/onrobot_rg2/collision/gripper_finger2_inner_knuckle_link.STL"/>
      </geometry>
    </collision>
  </link>

  <joint name="gripper_finger2_inner_knuckle_joint" type="continuous">
    <origin rpy="0 0 0" xyz="-0.0076 -0.01 0.1215"/>
    <parent link="gripper_base_link"/>
    <child link="gripper_finger2_inner_knuckle_link"/>
    <axis xyz="0 1 0"/>
    <limit effort="0.1" lower="-3.14" upper="3.14" velocity="100"/>
    <mimic joint="gripper_finger1_joint" multiplier="-1"/>
  </joint>
  <link name="gripper_finger2_finger_tip_link">
    <contact>
      <lateral_friction value="1.0"/>
      <spinning_friction value="1.5"/>
    </contact>
    <inertial>
      <origin rpy="0 0 0" xyz="0.00115944166678269 0.00579999927481416 0.0107764194581964"/>
      <mass value="0.00872849065417814"/>
      <inertia ixx="1.50886455139492E-06" ixy="-1.78552622842378E-14" ixz="-2.60234059895028E-07" iyy="1.45214737233688E-06" iyz="-9.3509454025756E-14" izz="3.57695503495603E-07"/>
    </inertial>
    <visual>
      <origin rpy="0 0 0" xyz="0 0 0"/>
      <geometry>
        <mesh filename="package://ur3/meshes/onrobot_rg2/visual/gripper_finger2_finger_tip_link.dae"/>
      </geometry>
      <material name="White">
        <color rgba="1 1 1 1"/>
      </material>
    </visual>
    <collision>
      <origin rpy="0 0 0" xyz="0 0 0"/>
      <geometry>
        <mesh filename="package://ur3/meshes/onrobot_rg2/collision/gripper_finger2_finger_tip_link.STL"/>
      </geometry>
    </collision>
  </link>

  <joint name="gripper_finger2_finger_tip_joint" type="continuous">
    <origin rpy="0 0 0" xyz="-0.002 0.0042 0.054964"/>
    <parent link="gripper_finger2_inner_knuckle_link"/>
    <child link="gripper_finger2_finger_tip_link"/>
    <axis xyz="0 1 0"/>
    <limit effort="0.1" lower="-3.14" upper="3.14" velocity="100"/>
    <mimic joint="gripper_finger1_joint" offset="0"/>
  </joint>


  <transmission name="gripper_finger1_trans">
    <type>transmission_interface/SimpleTransmission</type>
    <joint name="gripper_finger1_joint">
      <hardwareInterface>hardware_interface/PositionJointInterface</hardwareInterface>
    </joint>
    <actuator name="gripper_finger1_motor">
      <mechanicalReduction>1</mechanicalReduction>
      <hardwareInterface>PositionJointInterface</hardwareInterface>
    </actuator>
  </transmission>

  <joint name="kinect2_joint" type="fixed">
    <origin rpy="0.0 1.57079632679 0.0" xyz="0.4 0 1.57"/>
    <parent link="world"/>
    <child link="kinect2_base_link"/>
  </joint>
  <link name="kinect2_base_link">
    <inertial>
      <origin rpy="0 0 0" xyz="-0.0028247 0.00047839 0.038307"/>
      <mass value="0.82085"/>
      <inertia ixx="0.0039702" ixy="0" ixz="0" iyy="0.00059235" iyz="0" izz="0.0041195"/>
    </inertial>
    <visual>
      <origin rpy="0 0 0" xyz="0 0 0"/>
      <geometry>
        <mesh filename="package://ur3/meshes/kinect_v2/kinect2.STL"/>
      </geometry>
      <material name="">
        <color rgba="0.5 0.5 0.5 1"/>
      </material>
    </visual>
    <collision>
      <origin rpy="0 0 0" xyz="0 0 0"/>
      <geometry>
        <mesh filename="package://ur3/meshes/kinect_v2/kinect2.STL"/>
      </geometry>
    </collision>
  </link>

  <!-- kinect2 rgb sensor physical attachment -->
  <joint name="kinect2_rgb_joint" type="fixed">
    <origin rpy="0 0 0" xyz="0.032 -0.095 0.042015"/>
    <parent link="kinect2_base_link"/>
    <child link="kinect2_rgb_link"/>
  </joint>
  <link name="kinect2_rgb_link"/>
  <!-- kinect2 rgb sensor frame -->
  <joint name="kinect2_rgb_optical_frame_joint" type="fixed">
    <origin rpy="-1.570795 0 -1.570795" xyz="0 0 0"/>
    <parent link="kinect2_rgb_link"/>
    <child link="kinect2_rgb_optical_frame"/>
  </joint>
  <link name="kinect2_rgb_optical_frame"/>

  <!-- kinect2 ir sensor physical attachment -->
  <joint name="kinect2_ir_joint" type="fixed">
    <origin rpy="0 0 0" xyz="0 0.05157 0"/>
    <parent link="kinect2_rgb_link"/>
    <child link="kinect2_ir_link"/>
  </joint>
  <link name="kinect2_ir_link"/>
  <!-- kinect2 ir sensor frame -->
  <joint name="kinect2_ir_optical_frame_joint" type="fixed">
    <origin rpy="-1.570795 0 -1.570795" xyz="0 0 0"/>
    <parent link="kinect2_ir_link"/>
    <child link="kinect2_ir_optical_frame"/>
  </joint>
  <link name="kinect2_ir_optical_frame"/>
</robot>

